Traceback (most recent call last):
  File "F:\Users\Taku\anaconda3\envs\dataviz\lib\site-packages\pymongo\pool.py", line 724, in receive_message
    return receive_message(self, request_id, self.max_message_size)
  File "F:\Users\Taku\anaconda3\envs\dataviz\lib\site-packages\pymongo\network.py", line 214, in receive_message
    data = _receive_data_on_socket(sock_info, length - 16, deadline)
  File "F:\Users\Taku\anaconda3\envs\dataviz\lib\site-packages\pymongo\network.py", line 286, in _receive_data_on_socket
    chunk_length = sock_info.sock.recv_into(mv[bytes_read:])
  File "F:\Users\Taku\anaconda3\envs\dataviz\lib\site-packages\pymongo\pyopenssl_context.py", line 129, in recv_into
    return self._call(super(_sslConn, self).recv_into, *args, **kwargs)
  File "F:\Users\Taku\anaconda3\envs\dataviz\lib\site-packages\pymongo\pyopenssl_context.py", line 107, in _call
    return call(*args, **kwargs)
  File "F:\Users\Taku\anaconda3\envs\dataviz\lib\site-packages\OpenSSL\SSL.py", line 1840, in recv_into
    self._raise_ssl_error(self._ssl, result)
  File "F:\Users\Taku\anaconda3\envs\dataviz\lib\site-packages\OpenSSL\SSL.py", line 1671, in _raise_ssl_error
    _raise_current_error()
  File "F:\Users\Taku\anaconda3\envs\dataviz\lib\site-packages\OpenSSL\_util.py", line 54, in exception_from_error_queue
    raise exception_type(errors)
OpenSSL.SSL.Error: [('SSL routines', 'ssl3_get_record', 'decryption failed or bad record mac')]

During handling of the above exception, another exception occurred:

Traceback (most recent call last):
  File "update_db.py", line 105, in get_data
    response = admin.get()
  File "F:\All Projects\projects\update_extension_data\website\grocery\shoprite\shoprite_api.py", line 28, in get
    db_helper.shoprite_retrieve_and_clean_data()
  File "F:\All Projects\projects\update_extension_data\website\grocery\shoprite\db_helper_shoprite.py", line 31, in shoprite_retrieve_and_clean_data
    df = self.load_from_db()
  File "F:\All Projects\projects\update_extension_data\website\grocery\shoprite\db_helper_shoprite.py", line 56, in load_from_db
    return pd.DataFrame(list(collection.find()))
  File "F:\Users\Taku\anaconda3\envs\dataviz\lib\site-packages\pymongo\cursor.py", line 1207, in next
    if len(self.__data) or self._refresh():
  File "F:\Users\Taku\anaconda3\envs\dataviz\lib\site-packages\pymongo\cursor.py", line 1144, in _refresh
    self.__send_message(g)
  File "F:\Users\Taku\anaconda3\envs\dataviz\lib\site-packages\pymongo\cursor.py", line 999, in __send_message
    response = client._run_operation_with_response(
  File "F:\Users\Taku\anaconda3\envs\dataviz\lib\site-packages\pymongo\mongo_client.py", line 1368, in _run_operation_with_response
    return self._retryable_read(
  File "F:\Users\Taku\anaconda3\envs\dataviz\lib\site-packages\pymongo\mongo_client.py", line 1471, in _retryable_read
    return func(session, server, sock_info, slave_ok)
  File "F:\Users\Taku\anaconda3\envs\dataviz\lib\site-packages\pymongo\mongo_client.py", line 1360, in _cmd
    return server.run_operation_with_response(
  File "F:\Users\Taku\anaconda3\envs\dataviz\lib\site-packages\pymongo\server.py", line 117, in run_operation_with_response
    reply = sock_info.receive_message(request_id)
  File "F:\Users\Taku\anaconda3\envs\dataviz\lib\site-packages\pymongo\pool.py", line 726, in receive_message
    self._raise_connection_failure(error)
  File "F:\Users\Taku\anaconda3\envs\dataviz\lib\site-packages\pymongo\pool.py", line 891, in _raise_connection_failure
    _raise_connection_failure(self.address, error)
  File "F:\Users\Taku\anaconda3\envs\dataviz\lib\site-packages\pymongo\pool.py", line 286, in _raise_connection_failure
    raise AutoReconnect(msg)
pymongo.errors.AutoReconnect: cluster0-shard-00-02.mcpct.mongodb.net:27017: [('SSL routines', 'ssl3_get_record', 'decryption failed or bad record mac')]
Received Error for ShopriteAdmin: AutoReconnect
ShopriteAdmin attempt number 1 
time: 0:02:45.828375


Traceback (most recent call last):
  File "update_db.py", line 105, in get_data
    response = admin.get()
  File "F:\All Projects\projects\update_extension_data\website\pc\computermania\computermania_api.py", line 19, in get
    ComputermaniaDbHelper().computermania_retrieve_and_clean_data()
  File "F:\All Projects\projects\update_extension_data\website\pc\computermania\db_helper_computermania.py", line 35, in computermania_retrieve_and_clean_data
    self.retrieve_and_clean_data(
  File "F:\All Projects\projects\update_extension_data\website\dummy_objects\dummy_db_helper.py", line 39, in retrieve_and_clean_data
    raise Exception(
Exception: Unable to fetch data from firebase.
Received Error for ComputermaniaAdmin: Exception
ComputermaniaAdmin attempt number 1 
time: 0:00:03.075095


Traceback (most recent call last):
  File "update_db.py", line 105, in get_data
    response = admin.get()
  File "F:\All Projects\projects\update_extension_data\website\pc\computermania\computermania_api.py", line 19, in get
    ComputermaniaDbHelper().computermania_retrieve_and_clean_data()
  File "F:\All Projects\projects\update_extension_data\website\pc\computermania\db_helper_computermania.py", line 35, in computermania_retrieve_and_clean_data
    self.retrieve_and_clean_data(
  File "F:\All Projects\projects\update_extension_data\website\dummy_objects\dummy_db_helper.py", line 39, in retrieve_and_clean_data
    raise Exception(
Exception: Unable to fetch data from firebase.
Received Error for ComputermaniaAdmin: Exception
ComputermaniaAdmin attempt number 2 
time: 0:00:02.276732


Traceback (most recent call last):
  File "update_db.py", line 105, in get_data
    response = admin.get()
  File "F:\All Projects\projects\update_extension_data\website\pc\computermania\computermania_api.py", line 19, in get
    ComputermaniaDbHelper().computermania_retrieve_and_clean_data()
  File "F:\All Projects\projects\update_extension_data\website\pc\computermania\db_helper_computermania.py", line 35, in computermania_retrieve_and_clean_data
    self.retrieve_and_clean_data(
  File "F:\All Projects\projects\update_extension_data\website\dummy_objects\dummy_db_helper.py", line 39, in retrieve_and_clean_data
    raise Exception(
Exception: Unable to fetch data from firebase.
Received Error for ComputermaniaAdmin: Exception
ComputermaniaAdmin attempt number 3 
time: 0:00:02.260444


Traceback (most recent call last):
  File "update_db.py", line 105, in get_data
    response = admin.get()
  File "F:\All Projects\projects\update_extension_data\website\pc\hifi\hifi_api.py", line 20, in get
    from website.pc.hifi.db_helper_hifi import HifiDbHelper
  File "F:\All Projects\projects\update_extension_data\website\pc\hifi\db_helper_hifi.py", line 2, in <module>
    from update_extension_data.config.config import AccessoriesConfig
ModuleNotFoundError: No module named 'update_extension_data'
Received Error for HifiAdmin: ModuleNotFoundError
HifiAdmin attempt number 1 
time: 0:00:00.151002


Traceback (most recent call last):
  File "update_db.py", line 105, in get_data
    response = admin.get()
  File "F:\All Projects\projects\update_extension_data\website\pc\hifi\hifi_api.py", line 20, in get
    from website.pc.hifi.db_helper_hifi import HifiDbHelper
  File "F:\All Projects\projects\update_extension_data\website\pc\hifi\db_helper_hifi.py", line 2, in <module>
    from update_extension_data.config.config import AccessoriesConfig
ModuleNotFoundError: No module named 'update_extension_data'
Received Error for HifiAdmin: ModuleNotFoundError
HifiAdmin attempt number 2 
time: 0:00:00.009999


Traceback (most recent call last):
  File "update_db.py", line 105, in get_data
    response = admin.get()
  File "F:\All Projects\projects\update_extension_data\website\pc\hifi\hifi_api.py", line 20, in get
    from website.pc.hifi.db_helper_hifi import HifiDbHelper
  File "F:\All Projects\projects\update_extension_data\website\pc\hifi\db_helper_hifi.py", line 2, in <module>
    from update_extension_data.config.config import AccessoriesConfig
ModuleNotFoundError: No module named 'update_extension_data'
Received Error for HifiAdmin: ModuleNotFoundError
HifiAdmin attempt number 3 
time: 0:00:00.011000


Traceback (most recent call last):
  File "update_db.py", line 105, in get_data
    response = admin.get()
  File "F:\All Projects\projects\update_extension_data\website\pc\takealot\takealot_api.py", line 24, in get
    TakealotDbHelper().takealot_retrieve_and_clean_data()
  File "F:\All Projects\projects\update_extension_data\website\pc\takealot\db_helper_takealot.py", line 28, in takealot_retrieve_and_clean_data
    self.retrieve_and_clean_data(
  File "F:\All Projects\projects\update_extension_data\website\dummy_objects\dummy_db_helper.py", line 39, in retrieve_and_clean_data
    raise Exception(
Exception: Unable to fetch data from firebase.
Received Error for TakealotAdmin: Exception
TakealotAdmin attempt number 1 
time: 0:00:03.536015


Traceback (most recent call last):
  File "update_db.py", line 105, in get_data
    response = admin.get()
  File "F:\All Projects\projects\update_extension_data\website\pc\takealot\takealot_api.py", line 24, in get
    TakealotDbHelper().takealot_retrieve_and_clean_data()
  File "F:\All Projects\projects\update_extension_data\website\pc\takealot\db_helper_takealot.py", line 28, in takealot_retrieve_and_clean_data
    self.retrieve_and_clean_data(
  File "F:\All Projects\projects\update_extension_data\website\dummy_objects\dummy_db_helper.py", line 39, in retrieve_and_clean_data
    raise Exception(
Exception: Unable to fetch data from firebase.
Received Error for TakealotAdmin: Exception
TakealotAdmin attempt number 2 
time: 0:00:08.272805


Traceback (most recent call last):
  File "update_db.py", line 105, in get_data
    response = admin.get()
  File "F:\All Projects\projects\update_extension_data\website\pc\takealot\takealot_api.py", line 24, in get
    TakealotDbHelper().takealot_retrieve_and_clean_data()
  File "F:\All Projects\projects\update_extension_data\website\pc\takealot\db_helper_takealot.py", line 28, in takealot_retrieve_and_clean_data
    self.retrieve_and_clean_data(
  File "F:\All Projects\projects\update_extension_data\website\dummy_objects\dummy_db_helper.py", line 39, in retrieve_and_clean_data
    raise Exception(
Exception: Unable to fetch data from firebase.
Received Error for TakealotAdmin: Exception
TakealotAdmin attempt number 3 
time: 0:00:03.376779


Traceback (most recent call last):
  File "update_db.py", line 105, in get_data
    response = admin.get()
  File "F:\All Projects\projects\update_extension_data\website\clothing\markham\markham_api.py", line 23, in get
    MarkhamDbHelper().markham_retrieve_and_clean_data()
  File "F:\All Projects\projects\update_extension_data\website\clothing\markham\db_helper_markham.py", line 27, in markham_retrieve_and_clean_data
    self.retrieve_and_clean_data(
  File "F:\All Projects\projects\update_extension_data\website\dummy_objects\dummy_db_helper.py", line 39, in retrieve_and_clean_data
    raise Exception(
Exception: Unable to fetch data from firebase.
Received Error for MarkhamAdmin: Exception
MarkhamAdmin attempt number 1 
time: 0:00:14.734824


Traceback (most recent call last):
  File "update_db.py", line 105, in get_data
    response = admin.get()
  File "F:\All Projects\projects\update_extension_data\website\clothing\markham\markham_api.py", line 23, in get
    MarkhamDbHelper().markham_retrieve_and_clean_data()
  File "F:\All Projects\projects\update_extension_data\website\clothing\markham\db_helper_markham.py", line 27, in markham_retrieve_and_clean_data
    self.retrieve_and_clean_data(
  File "F:\All Projects\projects\update_extension_data\website\dummy_objects\dummy_db_helper.py", line 39, in retrieve_and_clean_data
    raise Exception(
Exception: Unable to fetch data from firebase.
Received Error for MarkhamAdmin: Exception
MarkhamAdmin attempt number 2 
time: 0:00:06.995509


Traceback (most recent call last):
  File "update_db.py", line 105, in get_data
    response = admin.get()
  File "F:\All Projects\projects\update_extension_data\website\clothing\markham\markham_api.py", line 23, in get
    MarkhamDbHelper().markham_retrieve_and_clean_data()
  File "F:\All Projects\projects\update_extension_data\website\clothing\markham\db_helper_markham.py", line 27, in markham_retrieve_and_clean_data
    self.retrieve_and_clean_data(
  File "F:\All Projects\projects\update_extension_data\website\dummy_objects\dummy_db_helper.py", line 39, in retrieve_and_clean_data
    raise Exception(
Exception: Unable to fetch data from firebase.
Received Error for MarkhamAdmin: Exception
MarkhamAdmin attempt number 3 
time: 0:00:02.571479


Traceback (most recent call last):
  File "update_db.py", line 105, in get_data
    response = admin.get()
  File "F:\All Projects\projects\update_extension_data\website\clothing\mrp\mrp_api.py", line 23, in get
    MrpDbHelper().mrp_retrieve_and_clean_data()
  File "F:\All Projects\projects\update_extension_data\website\clothing\mrp\db_helper_mrp.py", line 23, in mrp_retrieve_and_clean_data
    self.dynamodb_retrieve_and_clean_data(
  File "F:\All Projects\projects\update_extension_data\website\dummy_objects\dummy_db_helper.py", line 50, in dynamodb_retrieve_and_clean_data
    df = DynamodbHelper.load_from_dynamodb(
  File "F:\All Projects\projects\update_extension_data\website\dummy_objects\dynamo_db_helper.py", line 49, in load_from_dynamodb
    response = table.scan(**scan_kwargs)
  File "F:\Users\Taku\anaconda3\envs\dataviz\lib\site-packages\boto3\resources\factory.py", line 520, in do_action
    response = action(self, *args, **kwargs)
  File "F:\Users\Taku\anaconda3\envs\dataviz\lib\site-packages\boto3\resources\action.py", line 83, in __call__
    response = getattr(parent.meta.client, operation_name)(*args, **params)
  File "F:\Users\Taku\anaconda3\envs\dataviz\lib\site-packages\botocore\client.py", line 357, in _api_call
    return self._make_api_call(operation_name, kwargs)
  File "F:\Users\Taku\anaconda3\envs\dataviz\lib\site-packages\botocore\client.py", line 676, in _make_api_call
    raise error_class(parsed_response, operation_name)
botocore.errorfactory.ProvisionedThroughputExceededException: An error occurred (ProvisionedThroughputExceededException) when calling the Scan operation (reached max retries: 9): The level of configured provisioned throughput for the table was exceeded. Consider increasing your provisioning level with the UpdateTable API.
Received Error for MrpAdmin: ProvisionedThroughputExceededException
MrpAdmin attempt number 1 
time: 0:01:03.912615


Traceback (most recent call last):
  File "update_db.py", line 105, in get_data
    response = admin.get()
  File "F:\All Projects\projects\update_extension_data\website\clothing\mrp\mrp_api.py", line 23, in get
    MrpDbHelper().mrp_retrieve_and_clean_data()
  File "F:\All Projects\projects\update_extension_data\website\clothing\mrp\db_helper_mrp.py", line 23, in mrp_retrieve_and_clean_data
    self.dynamodb_retrieve_and_clean_data(
  File "F:\All Projects\projects\update_extension_data\website\dummy_objects\dummy_db_helper.py", line 50, in dynamodb_retrieve_and_clean_data
    df = DynamodbHelper.load_from_dynamodb(
  File "F:\All Projects\projects\update_extension_data\website\dummy_objects\dynamo_db_helper.py", line 49, in load_from_dynamodb
    response = table.scan(**scan_kwargs)
  File "F:\Users\Taku\anaconda3\envs\dataviz\lib\site-packages\boto3\resources\factory.py", line 520, in do_action
    response = action(self, *args, **kwargs)
  File "F:\Users\Taku\anaconda3\envs\dataviz\lib\site-packages\boto3\resources\action.py", line 83, in __call__
    response = getattr(parent.meta.client, operation_name)(*args, **params)
  File "F:\Users\Taku\anaconda3\envs\dataviz\lib\site-packages\botocore\client.py", line 357, in _api_call
    return self._make_api_call(operation_name, kwargs)
  File "F:\Users\Taku\anaconda3\envs\dataviz\lib\site-packages\botocore\client.py", line 676, in _make_api_call
    raise error_class(parsed_response, operation_name)
botocore.errorfactory.ProvisionedThroughputExceededException: An error occurred (ProvisionedThroughputExceededException) when calling the Scan operation (reached max retries: 9): The level of configured provisioned throughput for the table was exceeded. Consider increasing your provisioning level with the UpdateTable API.
Received Error for MrpAdmin: ProvisionedThroughputExceededException
MrpAdmin attempt number 2 
time: 0:00:37.961331


Traceback (most recent call last):
  File "update_db.py", line 105, in get_data
    response = admin.get()
  File "F:\All Projects\projects\update_extension_data\website\clothing\mrp\mrp_api.py", line 23, in get
    MrpDbHelper().mrp_retrieve_and_clean_data()
  File "F:\All Projects\projects\update_extension_data\website\clothing\mrp\db_helper_mrp.py", line 23, in mrp_retrieve_and_clean_data
    self.dynamodb_retrieve_and_clean_data(
  File "F:\All Projects\projects\update_extension_data\website\dummy_objects\dummy_db_helper.py", line 50, in dynamodb_retrieve_and_clean_data
    df = DynamodbHelper.load_from_dynamodb(
  File "F:\All Projects\projects\update_extension_data\website\dummy_objects\dynamo_db_helper.py", line 49, in load_from_dynamodb
    response = table.scan(**scan_kwargs)
  File "F:\Users\Taku\anaconda3\envs\dataviz\lib\site-packages\boto3\resources\factory.py", line 520, in do_action
    response = action(self, *args, **kwargs)
  File "F:\Users\Taku\anaconda3\envs\dataviz\lib\site-packages\boto3\resources\action.py", line 83, in __call__
    response = getattr(parent.meta.client, operation_name)(*args, **params)
  File "F:\Users\Taku\anaconda3\envs\dataviz\lib\site-packages\botocore\client.py", line 357, in _api_call
    return self._make_api_call(operation_name, kwargs)
  File "F:\Users\Taku\anaconda3\envs\dataviz\lib\site-packages\botocore\client.py", line 676, in _make_api_call
    raise error_class(parsed_response, operation_name)
botocore.errorfactory.ProvisionedThroughputExceededException: An error occurred (ProvisionedThroughputExceededException) when calling the Scan operation (reached max retries: 9): The level of configured provisioned throughput for the table was exceeded. Consider increasing your provisioning level with the UpdateTable API.
Received Error for MrpAdmin: ProvisionedThroughputExceededException
MrpAdmin attempt number 3 
time: 0:00:32.550230


Traceback (most recent call last):
  File "update_db.py", line 105, in get_data
    response = admin.get()
  File "F:\All Projects\projects\update_extension_data\website\clothing\sportscene\sportscene_api.py", line 14, in get
    from website.clothing.sportscene.db_helper_sportscene import SportsceneDbHelper
  File "F:\All Projects\projects\update_extension_data\website\clothing\sportscene\db_helper_sportscene.py", line 2, in <module>
    from update_extension_data.config.config import AccessoriesConfig
ModuleNotFoundError: No module named 'update_extension_data'
Received Error for SportsceneAdmin: ModuleNotFoundError
SportsceneAdmin attempt number 1 
time: 0:00:00.062487


Traceback (most recent call last):
  File "update_db.py", line 105, in get_data
    response = admin.get()
  File "F:\All Projects\projects\update_extension_data\website\clothing\sportscene\sportscene_api.py", line 14, in get
    from website.clothing.sportscene.db_helper_sportscene import SportsceneDbHelper
  File "F:\All Projects\projects\update_extension_data\website\clothing\sportscene\db_helper_sportscene.py", line 2, in <module>
    from update_extension_data.config.config import AccessoriesConfig
ModuleNotFoundError: No module named 'update_extension_data'
Received Error for SportsceneAdmin: ModuleNotFoundError
SportsceneAdmin attempt number 2 
time: 0:00:00.015627


Traceback (most recent call last):
  File "update_db.py", line 105, in get_data
    response = admin.get()
  File "F:\All Projects\projects\update_extension_data\website\clothing\sportscene\sportscene_api.py", line 14, in get
    from website.clothing.sportscene.db_helper_sportscene import SportsceneDbHelper
  File "F:\All Projects\projects\update_extension_data\website\clothing\sportscene\db_helper_sportscene.py", line 2, in <module>
    from update_extension_data.config.config import AccessoriesConfig
ModuleNotFoundError: No module named 'update_extension_data'
Received Error for SportsceneAdmin: ModuleNotFoundError
SportsceneAdmin attempt number 3 
time: 0:00:00


Traceback (most recent call last):
  File "F:\Users\Taku\anaconda3\envs\dataviz\lib\site-packages\urllib3\connection.py", line 159, in _new_conn
    conn = connection.create_connection(
  File "F:\Users\Taku\anaconda3\envs\dataviz\lib\site-packages\urllib3\util\connection.py", line 61, in create_connection
    for res in socket.getaddrinfo(host, port, family, socket.SOCK_STREAM):
  File "F:\Users\Taku\anaconda3\envs\dataviz\lib\socket.py", line 918, in getaddrinfo
    for res in _socket.getaddrinfo(host, port, family, type, proto, flags):
socket.gaierror: [Errno 11001] getaddrinfo failed

During handling of the above exception, another exception occurred:

Traceback (most recent call last):
  File "F:\Users\Taku\anaconda3\envs\dataviz\lib\site-packages\botocore\httpsession.py", line 314, in send
    urllib_response = conn.urlopen(
  File "F:\Users\Taku\anaconda3\envs\dataviz\lib\site-packages\urllib3\connectionpool.py", line 726, in urlopen
    retries = retries.increment(
  File "F:\Users\Taku\anaconda3\envs\dataviz\lib\site-packages\urllib3\util\retry.py", line 386, in increment
    raise six.reraise(type(error), error, _stacktrace)
  File "F:\Users\Taku\anaconda3\envs\dataviz\lib\site-packages\urllib3\packages\six.py", line 735, in reraise
    raise value
  File "F:\Users\Taku\anaconda3\envs\dataviz\lib\site-packages\urllib3\connectionpool.py", line 670, in urlopen
    httplib_response = self._make_request(
  File "F:\Users\Taku\anaconda3\envs\dataviz\lib\site-packages\urllib3\connectionpool.py", line 381, in _make_request
    self._validate_conn(conn)
  File "F:\Users\Taku\anaconda3\envs\dataviz\lib\site-packages\urllib3\connectionpool.py", line 978, in _validate_conn
    conn.connect()
  File "F:\Users\Taku\anaconda3\envs\dataviz\lib\site-packages\urllib3\connection.py", line 309, in connect
    conn = self._new_conn()
  File "F:\Users\Taku\anaconda3\envs\dataviz\lib\site-packages\urllib3\connection.py", line 171, in _new_conn
    raise NewConnectionError(
urllib3.exceptions.NewConnectionError: <botocore.awsrequest.AWSHTTPSConnection object at 0x000001F1DE20CEE0>: Failed to establish a new connection: [Errno 11001] getaddrinfo failed

During handling of the above exception, another exception occurred:

Traceback (most recent call last):
  File "update_db.py", line 105, in get_data
    response = admin.get()
  File "F:\All Projects\projects\update_extension_data\website\clothing\superbalist\superbalist_api.py", line 18, in get
    SuperbalistDbHelper().superbalist_retrieve_and_clean_data()
  File "F:\All Projects\projects\update_extension_data\website\clothing\superbalist\db_helper_superbalist.py", line 39, in superbalist_retrieve_and_clean_data
    self.dynamodb_retrieve_and_clean_data(
  File "F:\All Projects\projects\update_extension_data\website\dummy_objects\dummy_db_helper.py", line 50, in dynamodb_retrieve_and_clean_data
    df = DynamodbHelper.load_from_dynamodb(
  File "F:\All Projects\projects\update_extension_data\website\dummy_objects\dynamo_db_helper.py", line 49, in load_from_dynamodb
    response = table.scan(**scan_kwargs)
  File "F:\Users\Taku\anaconda3\envs\dataviz\lib\site-packages\boto3\resources\factory.py", line 520, in do_action
    response = action(self, *args, **kwargs)
  File "F:\Users\Taku\anaconda3\envs\dataviz\lib\site-packages\boto3\resources\action.py", line 83, in __call__
    response = getattr(parent.meta.client, operation_name)(*args, **params)
  File "F:\Users\Taku\anaconda3\envs\dataviz\lib\site-packages\botocore\client.py", line 357, in _api_call
    return self._make_api_call(operation_name, kwargs)
  File "F:\Users\Taku\anaconda3\envs\dataviz\lib\site-packages\botocore\client.py", line 662, in _make_api_call
    http, parsed_response = self._make_request(
  File "F:\Users\Taku\anaconda3\envs\dataviz\lib\site-packages\botocore\client.py", line 682, in _make_request
    return self._endpoint.make_request(operation_model, request_dict)
  File "F:\Users\Taku\anaconda3\envs\dataviz\lib\site-packages\botocore\endpoint.py", line 102, in make_request
    return self._send_request(request_dict, operation_model)
  File "F:\Users\Taku\anaconda3\envs\dataviz\lib\site-packages\botocore\endpoint.py", line 136, in _send_request
    while self._needs_retry(attempts, operation_model, request_dict,
  File "F:\Users\Taku\anaconda3\envs\dataviz\lib\site-packages\botocore\endpoint.py", line 253, in _needs_retry
    responses = self._event_emitter.emit(
  File "F:\Users\Taku\anaconda3\envs\dataviz\lib\site-packages\botocore\hooks.py", line 356, in emit
    return self._emitter.emit(aliased_event_name, **kwargs)
  File "F:\Users\Taku\anaconda3\envs\dataviz\lib\site-packages\botocore\hooks.py", line 228, in emit
    return self._emit(event_name, kwargs)
  File "F:\Users\Taku\anaconda3\envs\dataviz\lib\site-packages\botocore\hooks.py", line 211, in _emit
    response = handler(**kwargs)
  File "F:\Users\Taku\anaconda3\envs\dataviz\lib\site-packages\botocore\retryhandler.py", line 183, in __call__
    if self._checker(attempts, response, caught_exception):
  File "F:\Users\Taku\anaconda3\envs\dataviz\lib\site-packages\botocore\retryhandler.py", line 250, in __call__
    should_retry = self._should_retry(attempt_number, response,
  File "F:\Users\Taku\anaconda3\envs\dataviz\lib\site-packages\botocore\retryhandler.py", line 277, in _should_retry
    return self._checker(attempt_number, response, caught_exception)
  File "F:\Users\Taku\anaconda3\envs\dataviz\lib\site-packages\botocore\retryhandler.py", line 316, in __call__
    checker_response = checker(attempt_number, response,
  File "F:\Users\Taku\anaconda3\envs\dataviz\lib\site-packages\botocore\retryhandler.py", line 222, in __call__
    return self._check_caught_exception(
  File "F:\Users\Taku\anaconda3\envs\dataviz\lib\site-packages\botocore\retryhandler.py", line 359, in _check_caught_exception
    raise caught_exception
  File "F:\Users\Taku\anaconda3\envs\dataviz\lib\site-packages\botocore\endpoint.py", line 200, in _do_get_response
    http_response = self._send(request)
  File "F:\Users\Taku\anaconda3\envs\dataviz\lib\site-packages\botocore\endpoint.py", line 269, in _send
    return self.http_session.send(request)
  File "F:\Users\Taku\anaconda3\envs\dataviz\lib\site-packages\botocore\httpsession.py", line 343, in send
    raise EndpointConnectionError(endpoint_url=request.url, error=e)
botocore.exceptions.EndpointConnectionError: Could not connect to the endpoint URL: "https://dynamodb.us-east-2.amazonaws.com/"
Received Error for SuperbalistAdmin: EndpointConnectionError
SuperbalistAdmin attempt number 1 
time: 0:42:03.592601


Traceback (most recent call last):
  File "update_db.py", line 105, in get_data
    response = admin.get()
  File "F:\All Projects\projects\update_extension_data\website\pc\computermania\computermania_api.py", line 19, in get
    ComputermaniaDbHelper().computermania_retrieve_and_clean_data()
  File "F:\All Projects\projects\update_extension_data\website\pc\computermania\db_helper_computermania.py", line 35, in computermania_retrieve_and_clean_data
    self.retrieve_and_clean_data(
  File "F:\All Projects\projects\update_extension_data\website\dummy_objects\dummy_db_helper.py", line 39, in retrieve_and_clean_data
    raise Exception(
Exception: Unable to fetch data from firebase.
Received Error for ComputermaniaAdmin: Exception
ComputermaniaAdmin attempt number 1 
time: 0:00:02.541470


Traceback (most recent call last):
  File "update_db.py", line 105, in get_data
    response = admin.get()
  File "F:\All Projects\projects\update_extension_data\website\pc\computermania\computermania_api.py", line 19, in get
    ComputermaniaDbHelper().computermania_retrieve_and_clean_data()
  File "F:\All Projects\projects\update_extension_data\website\pc\computermania\db_helper_computermania.py", line 35, in computermania_retrieve_and_clean_data
    self.retrieve_and_clean_data(
  File "F:\All Projects\projects\update_extension_data\website\dummy_objects\dummy_db_helper.py", line 39, in retrieve_and_clean_data
    raise Exception(
Exception: Unable to fetch data from firebase.
Received Error for ComputermaniaAdmin: Exception
ComputermaniaAdmin attempt number 2 
time: 0:00:02.388545


Traceback (most recent call last):
  File "update_db.py", line 105, in get_data
    response = admin.get()
  File "F:\All Projects\projects\update_extension_data\website\pc\computermania\computermania_api.py", line 19, in get
    ComputermaniaDbHelper().computermania_retrieve_and_clean_data()
  File "F:\All Projects\projects\update_extension_data\website\pc\computermania\db_helper_computermania.py", line 35, in computermania_retrieve_and_clean_data
    self.retrieve_and_clean_data(
  File "F:\All Projects\projects\update_extension_data\website\dummy_objects\dummy_db_helper.py", line 39, in retrieve_and_clean_data
    raise Exception(
Exception: Unable to fetch data from firebase.
Received Error for ComputermaniaAdmin: Exception
ComputermaniaAdmin attempt number 3 
time: 0:00:02.290132


Traceback (most recent call last):
  File "update_db.py", line 105, in get_data
    response = admin.get()
  File "F:\All Projects\projects\update_extension_data\website\pc\hifi\hifi_api.py", line 20, in get
    from website.pc.hifi.db_helper_hifi import HifiDbHelper
  File "F:\All Projects\projects\update_extension_data\website\pc\hifi\db_helper_hifi.py", line 2, in <module>
    from update_extension_data.config.config import AccessoriesConfig
ModuleNotFoundError: No module named 'update_extension_data'
Received Error for HifiAdmin: ModuleNotFoundError
HifiAdmin attempt number 1 
time: 0:00:00.049043


Traceback (most recent call last):
  File "update_db.py", line 105, in get_data
    response = admin.get()
  File "F:\All Projects\projects\update_extension_data\website\pc\hifi\hifi_api.py", line 20, in get
    from website.pc.hifi.db_helper_hifi import HifiDbHelper
  File "F:\All Projects\projects\update_extension_data\website\pc\hifi\db_helper_hifi.py", line 2, in <module>
    from update_extension_data.config.config import AccessoriesConfig
ModuleNotFoundError: No module named 'update_extension_data'
Received Error for HifiAdmin: ModuleNotFoundError
HifiAdmin attempt number 2 
time: 0:00:00.010003


Traceback (most recent call last):
  File "update_db.py", line 105, in get_data
    response = admin.get()
  File "F:\All Projects\projects\update_extension_data\website\pc\hifi\hifi_api.py", line 20, in get
    from website.pc.hifi.db_helper_hifi import HifiDbHelper
  File "F:\All Projects\projects\update_extension_data\website\pc\hifi\db_helper_hifi.py", line 2, in <module>
    from update_extension_data.config.config import AccessoriesConfig
ModuleNotFoundError: No module named 'update_extension_data'
Received Error for HifiAdmin: ModuleNotFoundError
HifiAdmin attempt number 3 
time: 0:00:00.014998


Traceback (most recent call last):
  File "update_db.py", line 105, in get_data
    response = admin.get()
  File "F:\All Projects\projects\update_extension_data\website\pc\takealot\takealot_api.py", line 24, in get
    TakealotDbHelper().takealot_retrieve_and_clean_data()
  File "F:\All Projects\projects\update_extension_data\website\pc\takealot\db_helper_takealot.py", line 28, in takealot_retrieve_and_clean_data
    self.retrieve_and_clean_data(
  File "F:\All Projects\projects\update_extension_data\website\dummy_objects\dummy_db_helper.py", line 39, in retrieve_and_clean_data
    raise Exception(
Exception: Unable to fetch data from firebase.
Received Error for TakealotAdmin: Exception
TakealotAdmin attempt number 1 
time: 0:00:03.761591


Traceback (most recent call last):
  File "update_db.py", line 105, in get_data
    response = admin.get()
  File "F:\All Projects\projects\update_extension_data\website\pc\takealot\takealot_api.py", line 24, in get
    TakealotDbHelper().takealot_retrieve_and_clean_data()
  File "F:\All Projects\projects\update_extension_data\website\pc\takealot\db_helper_takealot.py", line 28, in takealot_retrieve_and_clean_data
    self.retrieve_and_clean_data(
  File "F:\All Projects\projects\update_extension_data\website\dummy_objects\dummy_db_helper.py", line 39, in retrieve_and_clean_data
    raise Exception(
Exception: Unable to fetch data from firebase.
Received Error for TakealotAdmin: Exception
TakealotAdmin attempt number 2 
time: 0:00:02.354665


Traceback (most recent call last):
  File "update_db.py", line 105, in get_data
    response = admin.get()
  File "F:\All Projects\projects\update_extension_data\website\pc\takealot\takealot_api.py", line 24, in get
    TakealotDbHelper().takealot_retrieve_and_clean_data()
  File "F:\All Projects\projects\update_extension_data\website\pc\takealot\db_helper_takealot.py", line 28, in takealot_retrieve_and_clean_data
    self.retrieve_and_clean_data(
  File "F:\All Projects\projects\update_extension_data\website\dummy_objects\dummy_db_helper.py", line 39, in retrieve_and_clean_data
    raise Exception(
Exception: Unable to fetch data from firebase.
Received Error for TakealotAdmin: Exception
TakealotAdmin attempt number 3 
time: 0:00:02.329379


Traceback (most recent call last):
  File "update_db.py", line 105, in get_data
    response = admin.get()
  File "F:\All Projects\projects\update_extension_data\website\clothing\markham\markham_api.py", line 23, in get
    MarkhamDbHelper().markham_retrieve_and_clean_data()
  File "F:\All Projects\projects\update_extension_data\website\clothing\markham\db_helper_markham.py", line 27, in markham_retrieve_and_clean_data
    self.retrieve_and_clean_data(
  File "F:\All Projects\projects\update_extension_data\website\dummy_objects\dummy_db_helper.py", line 39, in retrieve_and_clean_data
    raise Exception(
Exception: Unable to fetch data from firebase.
Received Error for MarkhamAdmin: Exception
MarkhamAdmin attempt number 1 
time: 0:00:02.482210


Traceback (most recent call last):
  File "update_db.py", line 105, in get_data
    response = admin.get()
  File "F:\All Projects\projects\update_extension_data\website\clothing\markham\markham_api.py", line 23, in get
    MarkhamDbHelper().markham_retrieve_and_clean_data()
  File "F:\All Projects\projects\update_extension_data\website\clothing\markham\db_helper_markham.py", line 27, in markham_retrieve_and_clean_data
    self.retrieve_and_clean_data(
  File "F:\All Projects\projects\update_extension_data\website\dummy_objects\dummy_db_helper.py", line 39, in retrieve_and_clean_data
    raise Exception(
Exception: Unable to fetch data from firebase.
Received Error for MarkhamAdmin: Exception
MarkhamAdmin attempt number 2 
time: 0:00:02.382540


Traceback (most recent call last):
  File "update_db.py", line 105, in get_data
    response = admin.get()
  File "F:\All Projects\projects\update_extension_data\website\clothing\markham\markham_api.py", line 23, in get
    MarkhamDbHelper().markham_retrieve_and_clean_data()
  File "F:\All Projects\projects\update_extension_data\website\clothing\markham\db_helper_markham.py", line 27, in markham_retrieve_and_clean_data
    self.retrieve_and_clean_data(
  File "F:\All Projects\projects\update_extension_data\website\dummy_objects\dummy_db_helper.py", line 39, in retrieve_and_clean_data
    raise Exception(
Exception: Unable to fetch data from firebase.
Received Error for MarkhamAdmin: Exception
MarkhamAdmin attempt number 3 
time: 0:00:02.320219


Traceback (most recent call last):
  File "update_db.py", line 105, in get_data
    response = admin.get()
  File "F:\All Projects\projects\update_extension_data\website\clothing\sportscene\sportscene_api.py", line 14, in get
    from website.clothing.sportscene.db_helper_sportscene import SportsceneDbHelper
  File "F:\All Projects\projects\update_extension_data\website\clothing\sportscene\db_helper_sportscene.py", line 2, in <module>
    from update_extension_data.config.config import AccessoriesConfig
ModuleNotFoundError: No module named 'update_extension_data'
Received Error for SportsceneAdmin: ModuleNotFoundError
SportsceneAdmin attempt number 1 
time: 0:00:00.074509


Traceback (most recent call last):
  File "update_db.py", line 105, in get_data
    response = admin.get()
  File "F:\All Projects\projects\update_extension_data\website\clothing\sportscene\sportscene_api.py", line 14, in get
    from website.clothing.sportscene.db_helper_sportscene import SportsceneDbHelper
  File "F:\All Projects\projects\update_extension_data\website\clothing\sportscene\db_helper_sportscene.py", line 2, in <module>
    from update_extension_data.config.config import AccessoriesConfig
ModuleNotFoundError: No module named 'update_extension_data'
Received Error for SportsceneAdmin: ModuleNotFoundError
SportsceneAdmin attempt number 2 
time: 0:00:00.024997


Traceback (most recent call last):
  File "update_db.py", line 105, in get_data
    response = admin.get()
  File "F:\All Projects\projects\update_extension_data\website\clothing\sportscene\sportscene_api.py", line 14, in get
    from website.clothing.sportscene.db_helper_sportscene import SportsceneDbHelper
  File "F:\All Projects\projects\update_extension_data\website\clothing\sportscene\db_helper_sportscene.py", line 2, in <module>
    from update_extension_data.config.config import AccessoriesConfig
ModuleNotFoundError: No module named 'update_extension_data'
Received Error for SportsceneAdmin: ModuleNotFoundError
SportsceneAdmin attempt number 3 
time: 0:00:00.029999


Traceback (most recent call last):
  File "update_db.py", line 105, in get_data
    response = admin.get()
  File "F:\All Projects\projects\update_extension_data\website\pc\hifi\hifi_api.py", line 20, in get
    from website.pc.hifi.db_helper_hifi import HifiDbHelper
  File "F:\All Projects\projects\update_extension_data\website\pc\hifi\db_helper_hifi.py", line 2, in <module>
    from update_extension_data.config.config import AccessoriesConfig
ModuleNotFoundError: No module named 'update_extension_data'
Received Error for HifiAdmin: ModuleNotFoundError
HifiAdmin attempt number 1 
time: 0:00:00.356591
finishing time: 2021-07-03 03:50:40.624679
starting time time: 2021-07-03 03:50:40.268088


Traceback (most recent call last):
  File "update_db.py", line 105, in get_data
    response = admin.get()
  File "F:\All Projects\projects\update_extension_data\website\pc\hifi\hifi_api.py", line 20, in get
    from website.pc.hifi.db_helper_hifi import HifiDbHelper
  File "F:\All Projects\projects\update_extension_data\website\pc\hifi\db_helper_hifi.py", line 2, in <module>
    from update_extension_data.config.config import AccessoriesConfig
ModuleNotFoundError: No module named 'update_extension_data'
Received Error for HifiAdmin: ModuleNotFoundError
HifiAdmin attempt number 2 
time: 0:00:00.008997
finishing time: 2021-07-03 03:50:40.634675
starting time time: 2021-07-03 03:50:40.625678


Traceback (most recent call last):
  File "update_db.py", line 105, in get_data
    response = admin.get()
  File "F:\All Projects\projects\update_extension_data\website\pc\hifi\hifi_api.py", line 20, in get
    from website.pc.hifi.db_helper_hifi import HifiDbHelper
  File "F:\All Projects\projects\update_extension_data\website\pc\hifi\db_helper_hifi.py", line 2, in <module>
    from update_extension_data.config.config import AccessoriesConfig
ModuleNotFoundError: No module named 'update_extension_data'
Received Error for HifiAdmin: ModuleNotFoundError
HifiAdmin attempt number 3 
time: 0:00:00.011992
finishing time: 2021-07-03 03:50:40.647675
starting time time: 2021-07-03 03:50:40.635683


Traceback (most recent call last):
  File "update_db.py", line 105, in get_data
    response = admin.get()
  File "F:\All Projects\projects\update_extension_data\website\pc\hifi\hifi_api.py", line 20, in get
    from website.pc.hifi.db_helper_hifi import HifiDbHelper
  File "F:\All Projects\projects\update_extension_data\website\pc\hifi\db_helper_hifi.py", line 2, in <module>
    from update_extension_data.config.config import AccessoriesConfig
ModuleNotFoundError: No module named 'update_extension_data'
Received Error for HifiAdmin: ModuleNotFoundError
HifiAdmin attempt number 1 
time: 0:00:00.093730
finishing time: 2021-07-03 05:20:34.979132
starting time time: 2021-07-03 05:20:34.885402


Traceback (most recent call last):
  File "update_db.py", line 105, in get_data
    response = admin.get()
  File "F:\All Projects\projects\update_extension_data\website\pc\hifi\hifi_api.py", line 20, in get
    from website.pc.hifi.db_helper_hifi import HifiDbHelper
  File "F:\All Projects\projects\update_extension_data\website\pc\hifi\db_helper_hifi.py", line 2, in <module>
    from update_extension_data.config.config import AccessoriesConfig
ModuleNotFoundError: No module named 'update_extension_data'
Received Error for HifiAdmin: ModuleNotFoundError
HifiAdmin attempt number 2 
time: 0:00:00.016001
finishing time: 2021-07-03 05:20:35.055483
starting time time: 2021-07-03 05:20:35.039482


Traceback (most recent call last):
  File "update_db.py", line 105, in get_data
    response = admin.get()
  File "F:\All Projects\projects\update_extension_data\website\pc\hifi\hifi_api.py", line 20, in get
    from website.pc.hifi.db_helper_hifi import HifiDbHelper
  File "F:\All Projects\projects\update_extension_data\website\pc\hifi\db_helper_hifi.py", line 2, in <module>
    from update_extension_data.config.config import AccessoriesConfig
ModuleNotFoundError: No module named 'update_extension_data'
Received Error for HifiAdmin: ModuleNotFoundError
HifiAdmin attempt number 3 
time: 0:00:00.007000
finishing time: 2021-07-03 05:20:35.063479
starting time time: 2021-07-03 05:20:35.056479


